Workbook

Sheet Cover Page
B2: {=_xlfn.XLOOKUP(C7, Projects!$A:$A, Projects!$B:$B) & " (" & C7 & ")"} -> Casa Spotify Miami (CSMIA26)
B3: EXECUTIVE PRODUCTION PLAYBOOK & OPERATING SPECIFICATION
B4: GHXSTSHIP Experiential Operating System (XOS 4.0 Standard) • Single Source of Truth (SSOT)
B6: EVENT PARAMETERS & TIMELINE | E6: CREATIVE & MARKETING NARRATIVE | H6: KEY CONTACTS & GOVERNANCE
B7: Project Code | C7: CSMIA26 | E7: Concept & Theme | F7: {=_xlfn.XLOOKUP(C7, Projects!$A:$A, Projects!$S:$S)} -> Art, Music & Technology Convergence in Wynwood; flagship production | H7: Executive Producer | I7: {=_xlfn.XLOOKUP(C7, Projects!$A:$A, Projects!$R:$R) & " (" & LOWER(SUBSTITUTE(_xlfn.XLOOKUP(C7, Projects!$A:$A, Projects!$R:$R), " ", ".")) & "@ghxstship.pro)"} -> Julian Clarkson (julian.clarkson@ghxstship.pro)
B8: Event Title | C8: {=_xlfn.XLOOKUP(C7, Projects!$A:$A, Projects!$B:$B)} -> Casa Spotify Miami | E8: Experience Tier | F8: {=_xlfn.XLOOKUP(C7, Projects!$A:$A, Projects!$J:$J)} -> Tier 06 Theatrical | H8: Organization | I8: {=_xlfn.XLOOKUP(C7, Projects!$A:$A, Projects!$D:$D)} -> GHXSTSHIP
B9: Event Anchor Date (T-0) | C9: {=_xlfn.XLOOKUP(C7, Projects!$A:$A, Projects!$I:$I)} -> 2026-10-16 | D9: (Anchor / Opening Day) | E9: Visual Identity | F9: =IF(C7="CSMIA26", "Wynwood Industrial Brutalism, LED Arrays, Neon", IF(C7="SXSW26", "Rainey Street Industrial, Warm Timber, Neon", IF(C7="EDCLV26", "Kinetic Cathedral, High-SPL LED, Lasers", IF(C7="ABMIA26", "Wynwood Arts Geometric, Minimalist Gallery", "Manhattan Editorial Runway, High-Gloss Monolith")))) -> Wynwood Industrial Brutalism, LED Arrays, Neon | H9: Operating Standard | I9: XOS 4.0 Experiential Operating System
B10: Show Dates | C10: {=TEXT(_xlfn.XLOOKUP(C7, Projects!$A:$A, Projects!$G:$G), "yyyy-mm-dd") & " to " & TEXT(_xlfn.XLOOKUP(C7, Projects!$A:$A, Projects!$H:$H), "yyyy-mm-dd")} -> 2026-08-21 to 2026-10-30 | E10: Audience Target | F10: =IF(C7="CSMIA26", "35,000 Daily Cap / 105,000 Weekend Aggregate", IF(C7="SXSW26", "2,500 Daily Cap / 10,000 Festival Aggregate", IF(C7="EDCLV26", "150,000 Daily Cap / 450,000 Weekend Aggregate", IF(C7="ABMIA26", "15,000 Daily Cap / 60,000 Event Aggregate", "5,000 Daily Cap / 15,000 Runway Aggregate")))) -> 35,000 Daily Cap / 105,000 Weekend Aggregate | H10: Jurisdiction & Code | I10: {=IF(_xlfn.XLOOKUP(C7, Projects!$A:$A, Projects!$F:$F)="Miami, FL", "US-FL-MIAMI-DADE (FBC / NFPA / City of Miami)", IF(_xlfn.XLOOKUP(C7, Projects!$A:$A, Projects!$F:$F)="Austin, TX", "US-TX-TRAVIS (City of Austin / IFC)", IF(_xlfn.XLOOKUP(C7, Projects!$A:$A, Projects!$F:$F)="Las Vegas, NV", "US-NV-CLARK (Clark County / IBC)", "US-NY-NEWYORK (NYC Building Code / FDNY)")))} -> US-FL-MIAMI-DADE (FBC / NFPA / City of Miami)
B11: Venue & Location | C11: {=_xlfn.XLOOKUP(C7, Projects!$A:$A, Projects!$E:$E) & ", " & _xlfn.XLOOKUP(C7, Projects!$A:$A, Projects!$F:$F)} -> Mana Wynwood Convention Center & Grounds, Miami, FL | E11: Acoustic Footprint | F11: =IF(C7="CSMIA26", "Multi-Zone High-SPL Controlled Environments", IF(C7="SXSW26", "Acoustic Showcase & Live Outdoor Stage", IF(C7="EDCLV26", "High-SPL Multi-Point Line Array Stadium Environment", IF(C7="ABMIA26", "Spatial Audio Gallery & Ambient Soundscape", "Runway Surround AVL & Broadcast Feed")))) -> Multi-Zone High-SPL Controlled Environments | H11: Governing Gate | I11: {=_xlfn.XLOOKUP(C7, Projects!$A:$A, Projects!$Q:$Q)} -> Gate 05 Build
B13: STAGE & PRODUCTION FOOTPRINT | E13: CURATED TALENT ROSTER & HIGHLIGHTS | H13: OPERATIONAL EXECUTION CADENCE
B14: =IF(C7="CSMIA26", "Main Stage (Zone B)", "Main Stage") -> Main Stage (Zone B) | C14: =IF(C7="CSMIA26", "60ft x 40ft Proscenium, Flown Line Arrays & 4K LED Backdrop", "Primary Production Footprint") -> 60ft x 40ft Proscenium, Flown Line Arrays & 4K LED Backdrop | E14: Headlining Acts | F14: =IF(C7="CSMIA26", "Latin & Global Headliners (TBA)", "Headlining Talent Roster") -> Latin & Global Headliners (TBA) | H14: Pre-Production Advance | I14: Gates 1–3: Scope, Engage, Advance (T-8W to T-4W)
B15: =IF(C7="CSMIA26", "Stage 2 - Tent Deck", "Secondary Stage") -> Stage 2 - Tent Deck | C15: =IF(C7="CSMIA26", "40ft x 30ft Covered Deck, Moving Head Rig & Cardioid Subs", "Secondary Production Footprint") -> 40ft x 30ft Covered Deck, Moving Head Rig & Cardioid Subs | E15: DJ & Electronic Sets | F15: =IF(C7="CSMIA26", "DJ SWVNLVKE & Resident Electronic Lineup", "Curated DJ & Electronic Sets") -> DJ SWVNLVKE & Resident Electronic Lineup | H15: Site Build & Load-In | I15: Gates 4–6: Procure, Build, Install (T-3W to T-1W)
B16: =IF(C7="CSMIA26", "VIP Oasis Lounge & El Patio", "VIP & Hospitality Lounge") -> VIP Oasis Lounge & El Patio | C16: =IF(C7="CSMIA26", "Curated Hospitality Terrace, Acoustic Salon & DJ Booth", "Hospitality Terrace & Acoustic Salon") -> Curated Hospitality Terrace, Acoustic Salon & DJ Booth | E16: Special Performances | F16: =IF(C7="CSMIA26", "Pop-Up Acoustic Sessions & Featured Artist Showcases", "Special Showcases & Guest Acts") -> Pop-Up Acoustic Sessions & Featured Artist Showcases | H16: Event Operations | I16: Gate 7: Operate (T-0, Live Run)
B17: Activation Compounds | C17: Sponsor brand footprints, retail hubs & food villages | E17: Broadcast & Sensory | F17: =IF(C7="CSMIA26", "Live Multicam 4K Stream, Spatial Audio & Cold-Air Scent", "4K Live Capture, Broadcast & Sensory") -> Live Multicam 4K Stream, Spatial Audio & Cold-Air Scent | H17: Strike & Reconciliation | I17: Gates 8–9: Strike, Amplify, Close (T+1W to T+2W)
B19: EXECUTIVE KPI SCOREBOARD & SYSTEM METRICS
B20: REVISED TOTAL BUDGET | D20: COMMITTED EXPENDITURE | F20: APPROVED CHANGE ORDERS | H20: PRODUCTION SCHEDULE TASKS
B21: {=_xlfn.XLOOKUP(C7, Projects!$A:$A, Projects!$K:$K)} -> 4500000 | D21: {=_xlfn.XLOOKUP(C7, Projects!$A:$A, Projects!$L:$L)} -> 46600 | F21: {=_xlfn.XLOOKUP(C7, Projects!$A:$A, Projects!$N:$N)} -> 1200 | H21: {=_xlfn.XLOOKUP(C7, Projects!$A:$A, Projects!$O:$O)} -> 3
B22: Approved Budget Envelope (Projects!K) | D22: Committed Spend (Projects!L) | F22: Approved Change Orders (Projects!N) | H22: Active Production Tasks (Projects!O)
B23: PROCUREMENT CATALOG ITEMS | D23: CRITICAL PATH MILESTONES | H23: SCHEDULE WORKBACK ENGINE
B24: =COUNTA('Procurement Catalog'!A2:A100) -> 1211 | D24: =COUNTIFS('Production Schedule'!$B:$B, C7, 'Production Schedule'!$R:$R, "Y") -> 20 | H24: =IF(ISBLANK(C9), "Anchor Date Required", "T-0 Locked: " & TEXT(C9, "yyyy-mm-dd") & " (" & IF(C9>TODAY(), "T-" & TEXT(C9-TODAY(), "#,##0") & " Days", IF(C9=TODAY(), "T-0 Live Today", "T+" & TEXT(TODAY()-C9, "#,##0") & " Days")) & ")") -> T-0 Locked: 2026-10-16 (T-8 Days)
B26: SYSTEM MODULE DIRECTORY & WORKBOOK NAVIGATION INDEX
B27: Functional Domain | C27: Primary Module | D27: Secondary Module | E27: Grain & Schema Scope | G27: Posture | H27: Governance & Classification
B28: Executive & Governance | C28: =HYPERLINK("#gid=1000100", "Projects") -> Projects | D28: =HYPERLINK("#gid=771928374", "Activity Log") -> Activity Log | E28: Master project portfolio, executive controls, governing gates & audit log | G28: Active Registry | H28: Executive Governance SSOT
B29: Production Planning & ROS | C29: =HYPERLINK("#gid=0", "Production Schedule") -> Production Schedule | D29: =HYPERLINK("#gid=7001030", "Run of Show") -> Run of Show | E29: 90 gated workback milestones, cue-by-cue run of show, tasks & work orders | G29: Dynamic Engine | H29: Production Operational SSOT
B30: Field Logistics & Assets | C30: =HYPERLINK("#gid=213042857", "Locations") -> Locations | D30: =HYPERLINK("#gid=300941203", "Shipping Manifest") -> Shipping Manifest | E30: Site locations, freight manifests, yard logs, advance hospitality & asset tracking | G30: Active Log | H30: Operational Field SSOT
B31: Workforce & Access | C31: =HYPERLINK("#gid=2117398587", "Personnel Roster") -> Personnel Roster | D31: =HYPERLINK("#gid=7001002", "Credential Issuance") -> Credential Issuance | E31: Staff roster, staffing requisitions, shift logs, rate cards & access grid | G31: Active Roster | H31: Workforce Governance
B32: Financial Controls & Commercial | C32: =HYPERLINK("#gid=900112244", "Budget Expenses") -> Budget Expenses | D32: =HYPERLINK("#gid=7001010", "Purchase Orders") -> Purchase Orders | E32: Cost center x GL x URID expenses, POs, change orders, procurement & vendors | G32: Active Ledger | H32: Fiscal Control Standard
B33: Safety & Compliance | C33: =HYPERLINK("#gid=7001001", "Inspection Compliance") -> Inspection Compliance | D33: =HYPERLINK("#gid=7001006", "Incident CAD Log") -> Incident CAD Log | E33: Agency safety inspections, incident CAD, emergency codes & comms channels | G33: Life Safety Standard | H33: Regulatory Compliance Standard
B34: Master Reference & Standards | C34: =HYPERLINK("#gid=8000101", "GL Accounts") -> GL Accounts | D34: =HYPERLINK("#gid=8000105", "Categories & URID Master") -> Categories & URID Master | E34: Chart of Accounts, 10 departments, 79 canon disciplines & matrix taxonomy | G34: Core Master | H34: Core Architecture Master

Sheet Projects
A1: PROJECT ID | B1: PROJECT NAME | C1: CLIENT NAME | D1: ORGANIZATION | E1: VENUE | F1: LOCATION | G1: START DATE | H1: END DATE | I1: ANCHOR DATE | J1: TIER | K1: BUDGET ENVELOPE | L1: COMMITTED AMOUNT | M1: ACTUAL SPEND | N1: APPROVED CHANGE ORDERS | O1: PRODUCTION TASKS | P1: OPERATIONAL STATE | Q1: GOVERNING GATE | R1: EXECUTIVE PRODUCER | S1: NOTES
A2: CSMIA26 | B2: Casa Spotify Miami | C2: Spotify | D2: GHXSTSHIP | E2: Mana Wynwood Convention Center & Grounds | F2: Miami, FL | G2: 2026-08-21 | H2: 2026-10-30 | I2: 2026-10-16 | J2: Tier 06 Theatrical | K2: 4500000 | L2: =SUMIFS('Budget Expenses'!$X:$X, 'Budget Expenses'!$B:$B, A2) -> 46600 | M2: =SUMIFS('Budget Expenses'!$Z:$Z, 'Budget Expenses'!$B:$B, A2) -> 0 | N2: =SUMIFS('Change Orders'!$M:$M, 'Change Orders'!$B:$B, A2, 'Change Orders'!$W:$W, "Approved") -> 1200 | O2: =COUNTIFS('Production Tasks'!$B:$B, A2, 'Production Tasks'!$V:$V, "Active") -> 3 | P2: Active | Q2: Gate 05 Build | R2: Julian Clarkson | S2: Art, Music & Technology Convergence in Wynwood; flagship production
A3: SXSW26 | B3: Spotify House Austin | C3: Spotify | D3: GHXSTSHIP | E3: Clive Bar & Rainey Footprint | F3: Austin, TX | G3: 2026-02-01 | H3: 2026-03-22 | I3: 2026-03-13 | J3: Tier 05 Experiential | K3: 2800000 | L3: =SUMIFS('Budget Expenses'!$X:$X, 'Budget Expenses'!$B:$B, A3) -> 0 | M3: =SUMIFS('Budget Expenses'!$Z:$Z, 'Budget Expenses'!$B:$B, A3) -> 0 | N3: =SUMIFS('Change Orders'!$M:$M, 'Change Orders'!$B:$B, A3, 'Change Orders'!$W:$W, "Approved") -> 0 | O3: =COUNTIFS('Production Tasks'!$B:$B, A3, 'Production Tasks'!$V:$V, "Active") -> 0 | P3: Complete | Q3: Gate 09 Close | R3: Julian Clarkson | S3: Interactive music showcase and brand activation; archived
A4: EDCLV26 | B4: Electric Daisy Carnival KineticFIELD | C4: Insomniac Events | D4: GHXSTSHIP | E4: Las Vegas Motor Speedway | F4: Las Vegas, NV | G4: 2026-04-10 | H4: 2026-05-25 | I4: 2026-05-15 | J4: Tier 06 Theatrical | K4: 6200000 | L4: =SUMIFS('Budget Expenses'!$X:$X, 'Budget Expenses'!$B:$B, A4) -> 0 | M4: =SUMIFS('Budget Expenses'!$Z:$Z, 'Budget Expenses'!$B:$B, A4) -> 0 | N4: =SUMIFS('Change Orders'!$M:$M, 'Change Orders'!$B:$B, A4, 'Change Orders'!$W:$W, "Approved") -> 0 | O4: =COUNTIFS('Production Tasks'!$B:$B, A4, 'Production Tasks'!$V:$V, "Active") -> 0 | P4: Complete | Q4: Gate 09 Close | R4: Tigre JC | S4: Mainstage scenic production, AVL engineering, and site ops
A5: ABMIA26 | B5: Art Basel Wynwood Experiential Pavilion | C5: Art Basel / UBS | D5: GHXSTSHIP | E5: Wynwood Arts District Pavilion | F5: Miami, FL | G5: 2026-10-01 | H5: 2026-12-10 | I5: 2026-12-03 | J5: Tier 05 Experiential | K5: 3400000 | L5: =SUMIFS('Budget Expenses'!$X:$X, 'Budget Expenses'!$B:$B, A5) -> 0 | M5: =SUMIFS('Budget Expenses'!$Z:$Z, 'Budget Expenses'!$B:$B, A5) -> 0 | N5: =SUMIFS('Change Orders'!$M:$M, 'Change Orders'!$B:$B, A5, 'Change Orders'!$W:$W, "Approved") -> 0 | O5: =COUNTIFS('Production Tasks'!$B:$B, A5, 'Production Tasks'!$V:$V, "Active") -> 0 | P5: Active | Q5: Gate 03 Advance | R5: Bex Izzy | S5: Immersive art installations, VIP hospitality lounge, and sensory exhibits
A6: NYFW26 | B6: NYFW Runway & Digital Immersion | C6: IMG Fashion | D6: GHXSTSHIP | E6: Spring Studios | F6: New York, NY | G6: 2026-11-15 | H6: 2027-02-20 | I6: 2027-02-11 | J6: Tier 06 Theatrical | K6: 3900000 | L6: =SUMIFS('Budget Expenses'!$X:$X, 'Budget Expenses'!$B:$B, A6) -> 0 | M6: =SUMIFS('Budget Expenses'!$Z:$Z, 'Budget Expenses'!$B:$B, A6) -> 0 | N6: =SUMIFS('Change Orders'!$M:$M, 'Change Orders'!$B:$B, A6, 'Change Orders'!$W:$W, "Approved") -> 0 | O6: =COUNTIFS('Production Tasks'!$B:$B, A6, 'Production Tasks'!$V:$V, "Active") -> 0 | P6: Scheduled | Q6: Gate 02 Engage | R6: Julian Clarkson | S6: High-concept fashion runway, broadcast capture, and digital streaming

Sheet Activity Log
A1: RECORD ID | B1: ORGANIZATION | C1: PROJECT | D1: DEPARTMENT | E1: CATEGORY | F1: SUB CATEGORY | G1: TIMESTAMP | H1: LOCATION / ZONE | I1: SUBJECT / ITEM | J1: DESCRIPTION | K1: PARTY INVOLVED | L1: QTY / VALUE | M1: PRIORITY | N1: LOGGED BY | O1: REFERENCE ID | P1: STATUS | Q1: FLAG | R1: NOTES | S1: CREATED BY | T1: CREATED AT | U1: UPDATED AT

Sheet Production Schedule
A1: ACTIVITY ID | B1: PROJECT ID | C1: PARENT ACTIVITY ID | D1: WBS CODE | E1: PHASE CODE | F1: PHASE | G1: ACT | H1: GATE | I1: ACTIVITY NAME | J1: ACTIVITY TYPE | K1: DELIVERABLE | L1: SOP ID | M1: OWNER ROLE | N1: PERSONNEL ID | O1: START DATE | P1: END DATE | Q1: DURATION (DAYS) | R1: CRITICAL PATH | S1: TOTAL TASKS | T1: COMPLETED TASKS | U1: PROGRESS (%) | V1: STATUS | W1: FLAG | X1: NOTES
A2: 0000-SCP-001 | B2: CSMIA26 | C2: G1-GATE-001 | D2: 1.1 | E2: SCP | F2: Scope | G2: PLAN | H2: 1 | I2: Approve event budget envelope and spend authority | J2: Summary Activity | K2: Event budget envelope memo | L2: SOP-022 | M2: TIGRE/JC | N2: P-021 | O2: 46255 | P2: 46268 | Q2: 14 | R2: Y | S2: =COUNTIF('Production Tasks'!$C$2:$C$25, A2) -> 2 | T2: =COUNTIFS('Production Tasks'!$C$2:$C$25, A2, 'Production Tasks'!$V$2:$V$25, "Complete") -> 2 | U2: =IF(S2>0, T2/S2, IF(V2="Complete", 1, 0)) -> 1 | V2: Complete | W2: FALSE | X2: Spend authority thresholds approved
A3: 1000-SCP-001 | B3: CSMIA26 | C3: G1-GATE-001 | D3: 1.2 | E3: SCP | F3: Scope | G3: PLAN | H3: 1 | I3: Define event creative concept & visual identity | J3: Summary Activity | K3: Creative brief & narrative deck | M3: BEX/IZZY | N3: P-006 | O3: 46255 | P3: 46268 | Q3: 14 | R3: Y | S3: =COUNTIF('Production Tasks'!$C$2:$C$25, A3) -> 1 | T3: =COUNTIFS('Production Tasks'!$C$2:$C$25, A3, 'Production Tasks'!$V$2:$V$25, "Complete") -> 1 | U3: =IF(S3>0, T3/S3, IF(V3="Complete", 1, 0)) -> 1 | V3: Complete | W3: FALSE | X3: Creative lock validated at Gate 1
A4: 2000-SCP-001 | B4: CSMIA26 | C4: G1-GATE-001 | D4: 1.3 | E4: SCP | F4: Scope | G4: PLAN | H4: 1 | I4: Lock talent lineup, set times & performance format | J4: Summary Activity | K4: Lineup curation memo | M4: IZZY | N4: P-005 | O4: 46255 | P4: 46268 | Q4: 14 | R4: Y | S4: =COUNTIF('Production Tasks'!$C$2:$C$25, A4) -> 0 | T4: =COUNTIFS('Production Tasks'!$C$2:$C$25, A4, 'Production Tasks'!$V$2:$V$25, "Complete") -> 0 | U4: =IF(S4>0, T4/S4, IF(V4="Complete", 1, 0)) -> 1 | V4: Complete | W4: FALSE | X4: Headliner and support roster locked
A5: G1-GATE-001 | B5: CSMIA26 | D5: 1 | E5: SCP | F5: Scope | G5: PLAN | H5: 1 | I5: Gate 1 Exit: Scope & Budget Lock Ratified | J5: Milestone Gate | K5: Gate 1 ratification memo | M5: TIGRE/JC | N5: P-021 | O5: 46268 | P5: 46268 | Q5: 0 | R5: Y | S5: =SUMIFS($S$2:$S$22, $C$2:$C$22, A5, $J$2:$J$22, "Summary Activity") -> 3 | T5: =SUMIFS($T$2:$T$22, $C$2:$C$22, A5, $J$2:$J$22, "Summary Activity") -> 3 | U5: =IF(S5>0, T5/S5, IF(V5="Complete", 1, 0)) -> 1 | V5: Complete | W5: FALSE | X5: Go/no-go milestone satisfied
A6: 0000-ENG-002 | B6: CSMIA26 | C6: G2-GATE-002 | D6: 2.1 | E6: ENG | F6: Engage | G6: PLAN | H6: 2 | I6: Execute master co-promoter & host agreements | J6: Summary Activity | K6: Executed co-promoter agreement | L6: SOP-022 | M6: JC/TIGRE | N6: P-021 | O6: 46269 | P6: 46282 | Q6: 14 | R6: Y | S6: =COUNTIF('Production Tasks'!$C$2:$C$25, A6) -> 2 | T6: =COUNTIFS('Production Tasks'!$C$2:$C$25, A6, 'Production Tasks'!$V$2:$V$25, "Complete") -> 2 | U6: =IF(S6>0, T6/S6, IF(V6="Complete", 1, 0)) -> 1 | V6: Complete | W6: FALSE | X6: Spotify and Tigre legal signoff complete
A7: 2000-ENG-002 | B7: CSMIA26 | C7: G2-GATE-002 | D7: 2.2 | E7: ENG | F7: Engage | G7: PLAN | H7: 2 | I7: Issue talent offers & execute performance contracts | J7: Summary Activity | K7: Executed talent contracts | L7: SOP-031 | M7: IZZY/TIGRE | N7: P-005 | O7: 46269 | P7: 46282 | Q7: 14 | R7: Y | S7: =COUNTIF('Production Tasks'!$C$2:$C$25, A7) -> 1 | T7: =COUNTIFS('Production Tasks'!$C$2:$C$25, A7, 'Production Tasks'!$V$2:$V$25, "Complete") -> 1 | U7: =IF(S7>0, T7/S7, IF(V7="Complete", 1, 0)) -> 1 | V7: Complete | W7: FALSE | X7: Deposit releases unblocked on execution
A8: G2-GATE-002 | B8: CSMIA26 | C8: G1-GATE-001 | D8: 2 | E8: ENG | F8: Engage | G8: PLAN | H8: 2 | I8: Gate 2 Exit: Contracting & Accountable Parties | J8: Milestone Gate | K8: Contract execution binder | L8: SOP-022 | M8: TIGRE/JC | N8: P-001 | O8: 46282 | P8: 46282 | Q8: 0 | R8: Y | S8: =SUMIFS($S$2:$S$22, $C$2:$C$22, A8, $J$2:$J$22, "Summary Activity") -> 3 | T8: =SUMIFS($T$2:$T$22, $C$2:$C$22, A8, $J$2:$J$22, "Summary Activity") -> 3 | U8: =IF(S8>0, T8/S8, IF(V8="Complete", 1, 0)) -> 1 | V8: Complete | W8: FALSE | X8: Zero unassigned scope requirements
A9: 0000-ADV-003 | B9: CSMIA26 | C9: G3-GATE-003 | D9: 3.1 | E9: ADV | F9: Advance | G9: PLAN | H9: 3 | I9: Confirm event certificates of insurance & endorsements | J9: Summary Activity | K9: Event COI binder | L9: SOP-022 | M9: TIGRE | N9: P-001 | O9: 46283 | P9: 46289 | Q9: 7 | R9: Y | S9: =COUNTIF('Production Tasks'!$C$2:$C$25, A9) -> 1 | T9: =COUNTIFS('Production Tasks'!$C$2:$C$25, A9, 'Production Tasks'!$V$2:$V$25, "Complete") -> 1 | U9: =IF(S9>0, T9/S9, IF(V9="Complete", 1, 0)) -> 1 | V9: Complete | W9: FALSE | X9: GL & liquor liability additional insureds on file
A10: 3000-ADV-003 | B10: CSMIA26 | C10: G3-GATE-003 | D10: 3.2 | E10: ADV | F10: Advance | G10: PLAN | H10: 3 | I10: Launch RSVP platform, ticketing tiers & invite list | J10: Summary Activity | K10: Live RSVP system | L10: SOP-028 | M10: JC/BEX | N10: P-006 | O10: 46283 | P10: 46289 | Q10: 7 | R10: Y | S10: =COUNTIF('Production Tasks'!$C$2:$C$25, A10) -> 1 | T10: =COUNTIFS('Production Tasks'!$C$2:$C$25, A10, 'Production Tasks'!$V$2:$V$25, "Complete") -> 1 | U10: =IF(S10>0, T10/S10, IF(V10="Complete", 1, 0)) -> 1 | V10: Complete | W10: FALSE | X10: Guest allocations verified
A11: G3-GATE-003 | B11: CSMIA26 | C11: G2-GATE-002 | D11: 3 | E11: ADV | F11: Advance | G11: PLAN | H11: 3 | I11: Gate 3 Exit: Advance & Baseline PO Lock | J11: Milestone Gate | K11: PO baseline register | M11: JC | N11: P-021 | O11: 46289 | P11: 46289 | Q11: 0 | R11: Y | S11: =SUMIFS($S$2:$S$22, $C$2:$C$22, A11, $J$2:$J$22, "Summary Activity") -> 2 | T11: =SUMIFS($T$2:$T$22, $C$2:$C$22, A11, $J$2:$J$22, "Summary Activity") -> 2 | U11: =IF(S11>0, T11/S11, IF(V11="Complete", 1, 0)) -> 1 | V11: Complete | W11: FALSE | X11: Permits filed; rigging verified
A12: 4000-PRC-004 | B12: CSMIA26 | C12: G4-GATE-004 | D12: 4.1 | E12: PRC | F12: Procure | G12: BUILD | H12: 4 | I12: Issue purchase orders for scenic, millwork & FF&E | J12: Summary Activity | K12: Fabrication purchase orders | L12: SOP-009 | M12: SMC/JC | N12: P-021 | O12: 46290 | P12: 46296 | Q12: 7 | R12: Y | S12: =COUNTIF('Production Tasks'!$C$2:$C$25, A12) -> 2 | T12: =COUNTIFS('Production Tasks'!$C$2:$C$25, A12, 'Production Tasks'!$V$2:$V$25, "Complete") -> 2 | U12: =IF(S12>0, T12/S12, IF(V12="Complete", 1, 0)) -> 1 | V12: Complete | W12: FALSE | X12: 3-week fabrication lead time lock
A13: G4-GATE-004 | B13: CSMIA26 | C13: G3-GATE-003 | D13: 4 | E13: PRC | F13: Procure | G13: BUILD | H13: 4 | I13: Gate 4 Exit: All Awards & Deposits Released | J13: Milestone Gate | K13: Deposit disbursements confirmation | M13: TIGRE | N13: P-001 | O13: 46296 | P13: 46296 | Q13: 0 | R13: Y | S13: =SUMIFS($S$2:$S$22, $C$2:$C$22, A13, $J$2:$J$22, "Summary Activity") -> 2 | T13: =SUMIFS($T$2:$T$22, $C$2:$C$22, A13, $J$2:$J$22, "Summary Activity") -> 2 | U13: =IF(S13>0, T13/S13, IF(V13="Complete", 1, 0)) -> 1 | V13: Complete | W13: FALSE | X13: All vendor awards issued
A14: 4000-BLD-005 | B14: CSMIA26 | C14: G5-GATE-005 | D14: 5.1 | E14: BLD | F14: Build | G14: BUILD | H14: 5 | I14: Pre-assemble modular bar wraps, DJ altar & lounge scenic | J14: Summary Activity | K14: Prefabricated components | L14: SOP-009 | M14: VENDOR/SMC | N14: P-021 | O14: 46297 | P14: 46306 | Q14: 10 | R14: Y | S14: =COUNTIF('Production Tasks'!$C$2:$C$25, A14) -> 2 | T14: =COUNTIFS('Production Tasks'!$C$2:$C$25, A14, 'Production Tasks'!$V$2:$V$25, "Complete") -> 0 | U14: =IF(S14>0, T14/S14, IF(V14="Complete", 1, 0)) -> 0 | V14: Active | W14: FALSE | X14: Shop prep and finishing off-site
A15: 5000-BLD-005 | B15: CSMIA26 | C15: G5-GATE-005 | D15: 5.2 | E15: BLD | F15: Build | G15: BUILD | H15: 5 | I15: Build stage decks, erect truss towers & hang line arrays | J15: Summary Activity | K15: Staging & truss structure | L15: SOP-001 | M15: VENDOR/JC | N15: P-021 | O15: 46297 | P15: 46306 | Q15: 10 | R15: Y | S15: =COUNTIF('Production Tasks'!$C$2:$C$25, A15) -> 2 | T15: =COUNTIFS('Production Tasks'!$C$2:$C$25, A15, 'Production Tasks'!$V$2:$V$25, "Complete") -> 1 | U15: =IF(S15>0, T15/S15, IF(V15="Complete", 1, 0)) -> 0.5 | V15: Active | W15: FALSE | X15: Rigging certification stamped
A16: G5-GATE-005 | B16: CSMIA26 | C16: G4-GATE-004 | D16: 5 | E16: BLD | F16: Build | G16: BUILD | H16: 5 | I16: Gate 5 Exit: Fabrication & Shop QC Pass | J16: Milestone Gate | K16: Shop QC signoff memo | L16: SOP-001 | M16: JC | N16: P-021 | O16: 46306 | P16: 46306 | Q16: 0 | R16: Y | S16: =SUMIFS($S$2:$S$22, $C$2:$C$22, A16, $J$2:$J$22, "Summary Activity") -> 4 | T16: =SUMIFS($T$2:$T$22, $C$2:$C$22, A16, $J$2:$J$22, "Summary Activity") -> 1 | U16: =IF(S16>0, T16/S16, IF(V16="Complete", 1, 0)) -> 0.25 | V16: Active | W16: FALSE | X16: Load-in dispatch unblocked
A17: 5000-INS-006 | B17: CSMIA26 | C17: G6-GATE-006 | D17: 6.1 | E17: INS | F17: Install | G17: BUILD | H17: 6 | I17: Connect power distro, commission audio & lighting timecode | J17: Summary Activity | K17: Commissioned AVL production rig | L17: SOP-002 | M17: JC | N17: P-021 | O17: 46307 | P17: 46310 | Q17: 4 | R17: Y | S17: =COUNTIF('Production Tasks'!$C$2:$C$25, A17) -> 2 | T17: =COUNTIFS('Production Tasks'!$C$2:$C$25, A17, 'Production Tasks'!$V$2:$V$25, "Complete") -> 0 | U17: =IF(S17>0, T17/S17, IF(V17="Complete", 1, 0)) -> 0 | V17: Scheduled | W17: FALSE | X17: Soundcheck & decibel compliance validated
A18: 6000-INS-006 | B18: CSMIA26 | C18: G6-GATE-006 | D18: 6.2 | E18: INS | F18: Install | G18: BUILD | H18: 6 | I18: Conduct safety & egress inspection with City of Miami Fire | J18: Summary Activity | K18: Fire Marshal inspection signoff | L18: SOP-005 | M18: JC/TIGRE | N18: P-021 | O18: 46307 | P18: 46310 | Q18: 4 | R18: Y | S18: =COUNTIF('Production Tasks'!$C$2:$C$25, A18) -> 2 | T18: =COUNTIFS('Production Tasks'!$C$2:$C$25, A18, 'Production Tasks'!$V$2:$V$25, "Complete") -> 0 | U18: =IF(S18>0, T18/S18, IF(V18="Complete", 1, 0)) -> 0 | V18: Scheduled | W18: FALSE | X18: Assembly occupancy permit granted
A19: G6-GATE-006 | B19: CSMIA26 | C19: G5-GATE-005 | D19: 6 | E19: INS | F19: Install | G19: BUILD | H19: 6 | I19: Gate 6 Exit: Operational Readiness Signoff | J19: Milestone Gate | K19: Readiness signoff memo | L19: SOP-004 | M19: JC/SPOTIFY | N19: P-021 | O19: 46310 | P19: 46310 | Q19: 0 | R19: Y | S19: =SUMIFS($S$2:$S$22, $C$2:$C$22, A19, $J$2:$J$22, "Summary Activity") -> 4 | T19: =SUMIFS($T$2:$T$22, $C$2:$C$22, A19, $J$2:$J$22, "Summary Activity") -> 0 | U19: =IF(S19>0, T19/S19, IF(V19="Complete", 1, 0)) -> 0 | V19: Scheduled | W19: FALSE | X19: Final go/no-go gate exit satisfied
A20: 7000-OPR-007 | B20: CSMIA26 | C20: G7-GATE-007 | D20: 7.1 | E20: OPR | F20: Operate | G20: SHOW | H20: 7 | I20: Host guest check-in, VIP activations & show live operations | J20: Summary Activity | K20: Incident log & daily ops report | L20: SOP-006 | M20: BEX/JC | N20: P-006 | O20: 46311 | P20: 46311 | Q20: 1 | R20: Y | S20: =COUNTIF('Production Tasks'!$C$2:$C$25, A20) -> 2 | T20: =COUNTIFS('Production Tasks'!$C$2:$C$25, A20, 'Production Tasks'!$V$2:$V$25, "Complete") -> 0 | U20: =IF(S20>0, T20/S20, IF(V20="Complete", 1, 0)) -> 0 | V20: Ready | W20: FALSE | X20: Doors open at 19:00 EDT
A21: 9000-AMP-008 | B21: CSMIA26 | C21: G7-GATE-007 | D21: 8.1 | E21: AMP | F21: Amplify | G21: SHOW | H21: 8 | I21: Broadcast distribution, media recap & footfall analytics | J21: Summary Activity | K21: Event data & analytics recap | L21: SOP-007 | M21: JC/BEX | N21: P-021 | O21: 46312 | P21: 46318 | Q21: 7 | R21: N | S21: =COUNTIF('Production Tasks'!$C$2:$C$25, A21) -> 2 | T21: =COUNTIFS('Production Tasks'!$C$2:$C$25, A21, 'Production Tasks'!$V$2:$V$25, "Complete") -> 0 | U21: =IF(S21>0, T21/S21, IF(V21="Complete", 1, 0)) -> 0 | V21: Ready | W21: FALSE | X21: Audience dwell & stream peak concurrents
A22: 0000-CLS-009 | B22: CSMIA26 | C22: G7-GATE-007 | D22: 9.1 | E22: CLS | F22: Close | G22: SHOW | H22: 9 | I22: Complete production strike, final ledger & closeouts | J22: Summary Activity | K22: Final financial cost report | L22: SOP-008 | M22: JC/TIGRE | N22: P-021 | O22: 46319 | P22: 46325 | Q22: 7 | R22: Y | S22: =COUNTIF('Production Tasks'!$C$2:$C$25, A22) -> 2 | T22: =COUNTIFS('Production Tasks'!$C$2:$C$25, A22, 'Production Tasks'!$V$2:$V$25, "Complete") -> 0 | U22: =IF(S22>0, T22/S22, IF(V22="Complete", 1, 0)) -> 0 | V22: Ready | W22: FALSE | X22: Reconciliation against Gate 3 baseline

Sheet Production Tasks
A1: TASK ID | B1: PROJECT ID | C1: ACTIVITY ID | D1: WBS CODE | E1: TASK NAME | F1: DESCRIPTION | G1: RECORD KIND | H1: RECORD SUBTYPE | I1: TEAM CODE | J1: LOCATION ID | K1: PERSONNEL ID | L1: ASSIGNEE NAME | M1: START DATE | N1: END DATE | O1: DURATION (DAYS) | P1: PREDECESSORS | Q1: PRIORITY | R1: DELIVERABLE | S1: LINKED WORK ORDER ID | T1: SOP ID | U1: PROGRESS (%) | V1: STATUS | W1: FLAG | X1: NOTES
A2: TSK-001 | B2: CSMIA26 | C2: 0000-SCP-001 | D2: 1.1.1 | E2: Draft spend envelope and authority matrix | F2: Define baseline budget limits and executive delegation of authority | G2: Task | H2: Define | I2: 0000-T01 | J2: LOC-03 | K2: P-021 | L2: Julian Clarkson | M2: 46255 | N2: 46261 | O2: 7 | Q2: Critical | R2: Approved spend thresholds memo | T2: SOP-022 | U2: 1 | V2: Complete | W2: FALSE | X2: Governed by SOP-022; Board envelope threshold sign-off
A3: TSK-002 | B3: CSMIA26 | C3: 0000-SCP-001 | D3: 1.1.2 | E3: Establish WBS chart of accounts mapping | F3: Align project expense items to master GL accounts and cost centers | G3: Task | H3: Coordinate | I3: 0000-T02 | J3: LOC-03 | K3: P-021 | L3: Julian Clarkson | M3: 46262 | N3: 46268 | O3: 7 | P3: TSK-001 | Q3: High | R3: Chart of accounts ledger map | U3: 1 | V3: Complete | W3: FALSE | X3: Reconciled with CC-VENUE and CC-CORP
A4: TSK-003 | B4: CSMIA26 | C4: 0000-ENG-002 | D4: 1.2.1 | E4: Negotiate co-promoter master agreement | F4: Finalize legal terms and liability provisions with co-promoter | G4: Task | H4: Coordinate | I4: 0000-T04 | J4: LOC-03 | K4: P-001 | L4: Ashley Sumner | M4: 46269 | N4: 46275 | O4: 7 | P4: TSK-002 | Q4: Critical | R4: Executed co-promoter contract | T4: SOP-031 | U4: 1 | V4: Complete | W4: FALSE | X4: Governed by SOP-031; Spotify and Tigre legal review
A5: TSK-004 | B5: CSMIA26 | C5: 0000-ENG-002 | D5: 1.2.2 | E5: Issue venue license and occupancy agreement | F5: Finalize primary site lease terms and indemnification clauses | G5: Task | H5: Execute | I5: 0000-T04 | J5: LOC-03 | K5: P-001 | L5: Ashley Sumner | M5: 46276 | N5: 46282 | O5: 7 | P5: TSK-003 | Q5: High | R5: Countersigned venue agreement | T5: SOP-034 | U5: 1 | V5: Complete | W5: FALSE | X5: Governed by SOP-034; Premises occupancy rider verified
A6: TSK-005 | B6: CSMIA26 | C6: 0000-ADV-003 | D6: 1.3.1 | E6: Bind general liability and excess umbrella policy | F6: Secure certificate of insurance with additional insured endorsements | G6: Task | H6: Verify | I6: 0000-T03 | J6: LOC-03 | K6: P-001 | L6: Ashley Sumner | M6: 46283 | N6: 46289 | O6: 7 | P6: TSK-004 | Q6: Critical | R6: Certificate of Insurance binder | T6: SOP-022 | U6: 1 | V6: Complete | W6: FALSE | X6: Governed by SOP-022; $5M aggregate limit compliance
A7: TSK-006 | B7: CSMIA26 | C7: 1000-SCP-001 | D7: 2.1.1 | E7: Publish creative identity guidelines and mood boards | F7: Establish color system, typographic hierarchy, and environmental guidelines | G7: Task | H7: Produce | I7: 1000-T01 | J7: LOC-03 | K7: P-006 | L7: Rebecca Bex | M7: 46255 | N7: 46268 | O7: 14 | Q7: High | R7: Visual identity brief deck | U7: 1 | V7: Complete | W7: FALSE | X7: Wynwood aesthetic alignment
A8: TSK-007 | B8: CSMIA26 | C8: 2000-ENG-002 | D8: 2.2.1 | E8: Issue artist offers and confirm headline performance | F8: Finalize talent deal memos, hospitality riders, and deposit schedules | G8: Task | H8: Execute | I8: 2000-T03 | J8: LOC-06 | K8: P-005 | L8: Isabella Acker | M8: 46269 | N8: 46282 | O8: 14 | P8: TSK-006 | Q8: Critical | R8: Executed artist performance contracts | T8: SOP-031 | U8: 1 | V8: Complete | W8: FALSE | X8: Governed by SOP-031; 50% deposit release authorized
A9: TSK-008 | B9: CSMIA26 | C9: 3000-ADV-003 | D9: 2.3.1 | E9: Deploy ticketing tiers and influencer RSVP portal | F9: Set up guest registration portal, VIP allocations, and tier validation | G9: Task | H9: Systems | I9: 3000-T01 | J9: LOC-03 | K9: P-006 | L9: Rebecca Bex | M9: 46283 | N9: 46289 | O9: 7 | P9: TSK-007 | Q9: High | R9: Live RSVP ticketing engine | T9: SOP-028 | U9: 1 | V9: Complete | W9: FALSE | X9: Governed by SOP-028; Capacity caps keyed to venue limits
A10: TSK-009 | B10: CSMIA26 | C10: 4000-PRC-004 | D10: 3.1.1 | E10: Order modular scenic wall panels and graphic skins | F10: Transmit fabrication specifications for stage backdrops and partitions | G10: Build | H10: Scenic | I10: 4000-T03 | J10: LOC-16 | K10: P-021 | L10: Julian Clarkson | M10: 46290 | N10: 46296 | O10: 7 | P10: TSK-008 | Q10: High | R10: Scenic fabrication purchase orders | S10: WO-002 | T10: SOP-009 | U10: 1 | V10: Complete | W10: FALSE | X10: Governed by SOP-009; Material flame-spread certification verified
A11: TSK-010 | B11: CSMIA26 | C11: 4000-PRC-004 | D11: 3.1.2 | E11: Contract FF&E lounge furniture and patio shade fixtures | F11: Procure designer sectionals, cocktail tables, and outdoor canopy hardware | G11: Task | H11: Coordinate | I11: 4000-T06 | J11: LOC-06 | K11: P-021 | L11: Julian Clarkson | M11: 46290 | N11: 46296 | O11: 7 | P11: TSK-009 | Q11: Medium | R11: FF&E vendor dispatch schedule | T11: SOP-009 | U11: 1 | V11: Complete | W11: FALSE | X11: Governed by SOP-009; Coordinated with SMC design specs
A12: TSK-011 | B12: CSMIA26 | C12: 4000-BLD-005 | D12: 3.2.1 | E12: Off-site fabrication of modular bar facades and DJ altar | F12: Millwork assembly, paint finishing, and edge LED channel integration | G12: Build | H12: Scenic | I12: 4000-T03 | J12: LOC-22 | K12: P-021 | L12: Julian Clarkson | M12: 46297 | N12: 46303 | O12: 7 | P12: TSK-010 | Q12: High | R12: Completed modular bar components | S12: WO-002 | T12: SOP-009 | U12: 0.8 | V12: Active | W12: FALSE | X12: Governed by SOP-009; Shop QC passed; awaiting load-in dispatch
A13: TSK-012 | B13: CSMIA26 | C13: 4000-BLD-005 | D13: 3.2.2 | E13: Pre-assemble neon signage frames and backdrop mounts | F13: Wire low-voltage transformers and test illuminated neon phrase fixtures | G13: Build | H13: Systems | I13: 4000-T07 | J13: LOC-16 | K13: P-006 | L13: Rebecca Bex | M13: 46301 | N13: 46306 | O13: 6 | P13: TSK-011 | Q13: Medium | R13: Pre-tested neon display assemblies | T13: SOP-002 | U13: 0.6 | V13: Active | W13: FALSE | X13: Governed by SOP-002; Exhibition room feature installation
A14: TSK-013 | B14: CSMIA26 | C14: 5000-BLD-005 | D14: 3.3.1 | E14: Erect stage decking and ground-support truss towers | F14: Assemble 4x8 decks with guardrails, ballast plates, and vertical motor masts | G14: Build | H14: Structural | I14: 5000-T05 | J14: LOC-01 | K14: P-021 | L14: Julian Clarkson | M14: 46297 | N14: 46301 | O14: 5 | P14: TSK-010 | Q14: Critical | R14: Structural stage and truss signoff | S14: WO-002 | T14: SOP-001 | U14: 1 | V14: Complete | W14: FALSE | X14: Governed by SOP-001; Rigging cert stamped by structural engineer
A15: TSK-014 | B15: CSMIA26 | C15: 5000-BLD-005 | D15: 3.3.2 | E15: Hang line array audio clusters and cardioid subwoofers | F15: Fly primary PA hangs, connect speaker multicores, and align front fills | G15: Build | H15: Systems | I15: 5000-T01 | J15: LOC-01 | K15: P-024 | L15: David Miller | M15: 46302 | N15: 46306 | O15: 5 | P15: TSK-013 | Q15: High | R15: Flown audio rig ready for tuning | S15: WO-001 | T15: SOP-001 | U15: 0.75 | V15: Active | W15: FALSE | X15: Governed by SOP-001; David Miller leading A1 hang
A16: TSK-015 | B16: CSMIA26 | C16: 5000-INS-006 | D16: 3.4.1 | E16: Connect temporary generator power distro and branch circuits | F16: Tie in primary 200A distro panels, test grounding, and balance phase loads | G16: Build | H16: Systems | I16: 5000-T04 | J16: LOC-01 | K16: P-021 | L16: Julian Clarkson | M16: 46307 | N16: 46308 | O16: 2 | P16: TSK-014 | Q16: Critical | R16: Certified power distribution network | S16: WO-001 | T16: SOP-002 | U16: 0 | V16: Scheduled | W16: FALSE | X16: Governed by SOP-002; Master electrician inspection prerequisite
A17: TSK-016 | B17: CSMIA26 | C17: 5000-INS-006 | D17: 3.4.2 | E17: Tune acoustic room curves and program lighting timecode | F17: Execute pink noise room alignment, timecode sync tests, and mover fixture presets | G17: Build | H17: Commissioning | I17: 5000-T01 | J17: LOC-01 | K17: P-024 | L17: David Miller | M17: 46309 | N17: 46310 | O17: 2 | P17: TSK-015 | Q17: High | R17: Commissioned AVL production system | S17: WO-001 | T17: SOP-003 | U17: 0 | V17: Scheduled | W17: FALSE | X17: Governed by SOP-003; Decibel limits validated for City of Miami noise variance
A18: TSK-017 | B18: CSMIA26 | C18: 6000-INS-006 | D18: 3.5.1 | E18: Conduct municipal life safety and fire marshal walkthrough | F18: Inspect egress corridors, fire extinguishers, panic hardware, and crowd barricades | G18: Inspection | H18: Safety | I18: 6000-T03 | J18: LOC-17 | K18: P-021 | L18: Julian Clarkson | M18: 46309 | N18: 46310 | O18: 2 | P18: TSK-016 | Q18: Critical | R18: Fire Marshal assembly occupancy permit | T18: SOP-005 | U18: 0 | V18: Scheduled | W18: FALSE | X18: Governed by SOP-005; AHJ signoff required prior to public doors
A19: TSK-018 | B19: CSMIA26 | C19: 6000-INS-006 | D19: 3.5.2 | E19: Brief security detail, crowd managers, and medical staff | F19: Review radio protocol, emergency evacuation routes, and threat escalation procedures | G19: Task | H19: Coordinate | I19: 6000-T05 | J19: LOC-03 | K19: P-016 | L19: Mary Christianson | M19: 46310 | N19: 46310 | O19: 1 | P19: TSK-017 | Q19: High | R19: Security deployment roster & sign-in | T19: SOP-004 | U19: 0 | V19: Scheduled | W19: FALSE | X19: Governed by SOP-004; City of Miami PD off-duty coordination
A20: TSK-019 | B20: CSMIA26 | C20: 7000-OPR-007 | D20: 4.1.1 | E20: Manage guest check-in, VIP wristbands, and credential scanning | F20: Operate front-of-house arrival portal, ticket scanners, and swag gift distribution | G20: Shift | H20: Show | I20: 7000-T03 | J20: LOC-02 | K20: P-006 | L20: Rebecca Bex | M20: 46311 | N20: 46311 | O20: 1 | P20: TSK-018 | Q20: High | R20: Guest entry log & scan counts | T20: SOP-028 | U20: 0 | V20: Ready | W20: FALSE | X20: Governed by SOP-028; Continuous sync with live attendance dashboard
A21: TSK-020 | B21: CSMIA26 | C21: 7000-OPR-007 | D21: 4.1.2 | E21: Direct main stage live performance and DJ show calling | F21: Coordinate stage management, cue lights, lighting presets, and talent changeovers | G21: Shift | H21: Show | I21: 2000-T01 | J21: LOC-01 | K21: P-021 | L21: Julian Clarkson | M21: 46311 | N21: 46311 | O21: 1 | P21: TSK-016 | Q21: Critical | R21: Flawless live show execution | T21: SOP-006 | U21: 0 | V21: Ready | W21: FALSE | X21: Governed by SOP-006; Run of show cues strictly maintained
A22: TSK-021 | B22: CSMIA26 | C22: 9000-AMP-008 | D22: 4.2.1 | E22: Ingest live multicam footage and encode press social reels | F22: Edit same-day highlights, color grade clips, and push media assets to PR distribution | G22: Task | H22: Produce | I22: 3000-T02 | J22: LOC-03 | K22: P-006 | L22: Rebecca Bex | M22: 46312 | N22: 46315 | O22: 4 | P22: TSK-020 | Q22: High | R22: Post-event media highlight reel | T22: SOP-007 | U22: 0 | V22: Ready | W22: FALSE | X22: Governed by SOP-007; Cleared usage rights on all tracks
A23: TSK-022 | B23: CSMIA26 | C23: 9000-AMP-008 | D23: 4.2.2 | E23: Aggregate attendance footfall and stream viewer analytics | F23: Compile RFID scan metrics, dwell heatmap reports, and social impression tallies | G23: Task | H23: Produce | I23: 9000-T04 | J23: LOC-03 | K23: P-021 | L23: Julian Clarkson | M23: 46312 | N23: 46318 | O23: 7 | P23: TSK-021 | Q23: Medium | R23: Analytics & ROI recap report | T23: SOP-028 | U23: 0 | V23: Ready | W23: FALSE | X23: Governed by SOP-028; Measures against Gate 1 KPI targets
A24: TSK-023 | B24: CSMIA26 | C24: 0000-CLS-009 | D24: 4.3.1 | E24: Strike production rigging and return equipment rentals | F24: De-rig line arrays, pack truss, disassemble staging, and load out carrier trucks | G24: Strike | H24: Show Strike | I24: 5000-T05 | J24: LOC-01 | K24: P-021 | L24: Julian Clarkson | M24: 46312 | N24: 46315 | O24: 4 | P24: TSK-020 | Q24: High | R24: Rental equipment return manifests | S24: WO-002 | T24: SOP-008 | U24: 0 | V24: Ready | W24: FALSE | X24: Governed by SOP-008; Zero damage disposition signoff
A25: TSK-024 | B25: CSMIA26 | C25: 0000-CLS-009 | D25: 4.3.2 | E25: Execute post-event financial settlement and bond releases | F25: Reconcile PO actuals against budget baseline and secure municipal deposit returns | G25: Task | H25: Verify | I25: 0000-T02 | J25: LOC-03 | K25: P-001 | L25: Ashley Sumner | M25: 46319 | N25: 46325 | O25: 7 | P25: TSK-023 | Q25: High | R25: Final financial reconciliation ledger | T25: SOP-034 | U25: 0 | V25: Ready | W25: FALSE | X25: Governed by SOP-034; Closeout signoff by Executive Producer

Sheet Work Orders
A1: RECORD ID | B1: PROJECT ID | C1: DEPARTMENT | D1: CATEGORY | E1: SUB CATEGORY | F1: WORK ORDER TYPE | G1: PRIORITY | H1: LOCATION ID | I1: LOCATION NAME | J1: ITEM ID | K1: TEAM CODE | L1: PERSONNEL ID | M1: LEAD ASSIGNEE NAME | N1: TASK TITLE | O1: DESCRIPTION | P1: SCOPE OF WORK | Q1: SCHEDULED START DATE | R1: SCHEDULED END DATE | S1: ACTUAL START DATE | T1: ACTUAL END DATE | U1: ESTIMATED HOURS | V1: ACTUAL HOURS | W1: LABOR RATE | X1: TOTAL LABOR COST | Y1: SAFETY HAZARD LEVEL | Z1: COMPLETION PERCENTAGE | AA1: STATUS | AB1: FLAG | AC1: RESOLUTION NOTES | AD1: NOTES | AE1: CREATED BY | AF1: CREATED AT | AG1: UPDATED AT
A2: WO-001 | B2: ='Cover Page'!$C$7 -> CSMIA26 | C2: 5000 Production | D2: 5000.01 Audio | E2: Audio Infrastructure | F2: AVL Installation | G2: Critical | H2: LOC-01 | I2: {=IF(ISBLANK(H2), "", _xlfn.XLOOKUP(H2, Locations!$A$2:$A100, Locations!$F$2:$F100, ""))} -> Zone B - Main Stage | J2: 5000.01.02-XPMS-004 | K2: 5000-T01 | L2: P-024 | M2: {=IF(ISBLANK(L2), "", TRIM(_xlfn.XLOOKUP(L2, 'Personnel Roster'!$A$2:$A100, 'Personnel Roster'!$D$2:$D100, "") & " " & _xlfn.XLOOKUP(L2, 'Personnel Roster'!$A$2:$A100, 'Personnel Roster'!$E$2:$E100, "")))} -> David Miller | N2: Main PA Line Array Hang and Calibration | O2: Install and tune main FOH line array system | P2: Acoustic sweep, time alignment, and safety cable inspection | Q2: 46310 | R2: 46311 | S2: 46310 | T2: 46311 | U2: 16 | V2: 14.5 | W2: 75 | X2: =V2*W2 -> 1087.5 | Y2: Medium | Z2: 1 | AA2: Completed | AB2: FALSE | AC2: System calibrated to 102 dBA target | AD2: Signed off by Technical Production Manager | AE2: Julian Clarkson | AF2: 46296 | AG2: 46311
A3: WO-002 | B3: ='Cover Page'!$C$7 -> CSMIA26 | C3: 4000 Environment | D3: 4000.01 Construction & Carpentry | E3: General Tools & Hardware | F3: Facility Setup | G3: High | H3: LOC-01 | I3: {=IF(ISBLANK(H3), "", _xlfn.XLOOKUP(H3, Locations!$A$2:$A100, Locations!$F$2:$F100, ""))} -> Zone B - Main Stage | J3: 4000.08.01-XPMS-001 | K3: 4000-T04 | L3: P-021 | M3: {=IF(ISBLANK(L3), "", TRIM(_xlfn.XLOOKUP(L3, 'Personnel Roster'!$A$2:$A100, 'Personnel Roster'!$D$2:$D100, "") & " " & _xlfn.XLOOKUP(L3, 'Personnel Roster'!$A$2:$A100, 'Personnel Roster'!$E$2:$E100, "")))} -> Julian Clarkson | N3: Stage Decks and Barricade Erection | O3: Assemble 4x8 modular stage decking and Mojo safety barricade | P3: Leveling, clamp torquing, and stage skirt attachment | Q3: 46313 | R3: 46314 | S3: 46313 | T3: 46314 | U3: 24 | V3: 22 | W3: 65 | X3: =V3*W3 -> 1430 | Y3: High | Z3: 1 | AA3: Completed | AB3: FALSE | AC3: Structural stability certified | AD3: Stagehand union crew utilized | AE3: Julian Clarkson | AF3: 46300 | AG3: 46314
A4: WO-003 | B4: ='Cover Page'!$C$7 -> CSMIA26 | C4: 9000 Technology | D4: 9000.52 Venue IT | E4: Network Provision | F4: Network Deployment | G4: High | H4: LOC-03 | I4: {=IF(ISBLANK(H4), "", _xlfn.XLOOKUP(H4, Locations!$A$2:$A100, Locations!$F$2:$F100, ""))} -> Production Office / Quartermaster | J4: 9000.01.01-XPMS-005 | K4: 9000-T06 | L4: P-021 | M4: {=IF(ISBLANK(L4), "", TRIM(_xlfn.XLOOKUP(L4, 'Personnel Roster'!$A$2:$A100, 'Personnel Roster'!$D$2:$D100, "") & " " & _xlfn.XLOOKUP(L4, 'Personnel Roster'!$A$2:$A100, 'Personnel Roster'!$E$2:$E100, "")))} -> Julian Clarkson | N4: Production Network VLAN Configuration | O4: Configure segregated VLANs for guest WiFi and broadcast telemetry | P4: Fiber patch to switches, router config, and bandwidth test | Q4: 46315 | R4: 46316 | S4: 46315 | T4: 46316 | U4: 12 | V4: 11.5 | W4: 85 | X4: =V4*W4 -> 977.5 | Y4: Low | Z4: 1 | AA4: Completed | AB4: FALSE | AC4: Network throughput validated at 1 Gbps | AD4: Tested with Toast POS hardware | AE4: Julian Clarkson | AF4: 46305 | AG4: 46316
A5: WO-004 | B5: ='Cover Page'!$C$7 -> CSMIA26 | C5: 6000 Operations | D5: 6000.04 Security & Access Control | E5: Security & Access Control | F5: Security Commissioning | G5: Medium | H5: LOC-08 | I5: {=IF(ISBLANK(H5), "", _xlfn.XLOOKUP(H5, Locations!$A$2:$A100, Locations!$F$2:$F100, ""))} -> Gate 2 - South Gate | J5: 9000.04.01-XPMS-002 | K5: 6000-T07 | L5: P-016 | M5: {=IF(ISBLANK(L5), "", TRIM(_xlfn.XLOOKUP(L5, 'Personnel Roster'!$A$2:$A100, 'Personnel Roster'!$D$2:$D100, "") & " " & _xlfn.XLOOKUP(L5, 'Personnel Roster'!$A$2:$A100, 'Personnel Roster'!$E$2:$E100, "")))} -> Mary Christianson | N5: Access Control and Magnetometer Deployment | O5: Install walk-through metal detectors and set ingress gates | P5: Power tie-in, sensitivity calibration, and barrier alignment | Q5: 46317 | R5: 46318 | S5: 46317 | U5: 10 | V5: 6 | W5: 55 | X5: =V5*W5 -> 330 | Y5: Medium | Z5: 0.6 | AA5: In Progress | AB5: FALSE | AC5: Hardware operational; awaiting final shift walk | AD5: Coordinated with City Fire Inspector | AE5: Julian Clarkson | AF5: 46307 | AG5: 46317
A6: WO-005 | B6: ='Cover Page'!$C$7 -> CSMIA26 | C6: 5000 Production | D6: 5000.02 Lighting | E6: Lighting Control | F6: Rigging & Focus | G6: High | H6: LOC-01 | I6: {=IF(ISBLANK(H6), "", _xlfn.XLOOKUP(H6, Locations!$A$2:$A100, Locations!$F$2:$F100, ""))} -> Zone B - Main Stage | J6: 5000.02.02-XPMS-004 | K6: 5000-T03 | L6: P-021 | M6: {=IF(ISBLANK(L6), "", TRIM(_xlfn.XLOOKUP(L6, 'Personnel Roster'!$A$2:$A100, 'Personnel Roster'!$D$2:$D100, "") & " " & _xlfn.XLOOKUP(L6, 'Personnel Roster'!$A$2:$A100, 'Personnel Roster'!$E$2:$E100, "")))} -> Julian Clarkson | N6: Overhead Lighting Truss Focus and DMX Addressing | O6: Hang moving heads and test Art-Net lighting universe control | P6: Safety wire secondary attachments, lamp check, and cue recording | Q6: 46320 | R6: 46321 | U6: 18 | V6: 0 | W6: 75 | X6: =V6*W6 -> 0 | Y6: High | Z6: 0 | AA6: Scheduled | AB6: FALSE | AC6: Pending rigger signoff | AD6: Focus scheduled for dark hours | AE6: Julian Clarkson | AF6: 46309 | AG6: 46309

Sheet Run of Show
A1: RECORD ID | B1: ORGANIZATION | C1: PROJECT ID | D1: SCHEDULE RECORD ID | E1: CUE ID | F1: ACT | G1: SCENE | H1: DESCRIPTION | I1: START TIME | J1: END TIME | K1: DURATION (MIN) | L1: LOCATION ID | M1: PERSONNEL ID | N1: AUDIO CUE | O1: LIGHTING CUE | P1: VIDEO CUE | Q1: SFX CUE | R1: STAGE CUE | S1: STATUS | T1: FLAG | U1: NOTES | V1: CREATED BY | W1: CREATED AT | X1: UPDATED AT
A2: ROS-001 | B2: GHXSTSHIP | C2: CSMIA26 | D2: 5000-OPR-007 | E2: CUE-01 | F2: Act I · Ingress & Warm-Up | G2: Doors Open & Guest Check-In | H2: Front of house doors open; guest credentials check and initial lounge activation | I2: 0.75 | J2: 0.77083333 | K2: 30 | L2: LOC-02 | M2: P-016 | N2: Ambient background music at 72 dBA; FOH mix standby | O2: Look 01 - Warm architectural wash & amber accents | P2: Looping Casa Spotify brand reel & sponsor logo matrix | Q2: Baseline atmospheric scent diffusion active; haze standby | R2: Stage dark; DJ gear line check verified; green rooms active | S2: Scheduled | T2: FALSE | U2: Coordinate arrival pace with door security; RFID scanning active | V2: Julian Clarkson | W2: 46297.413 | X2: 46297.413
A3: ROS-002 | B3: GHXSTSHIP | C3: CSMIA26 | D3: 5000-OPR-007 | E3: CUE-02 | F3: Act I · Ingress & Warm-Up | G3: Support DJ Set & Cocktail Reception | H3: Opening support DJ set building energy across the sanctuary floor and patio | I3: 0.77083333 | J3: 0.8125 | K3: 60 | L3: LOC-01 | M3: P-024 | N3: DJ direct input hot; live stereo mains at 85 dBA | O3: Look 02 - Subtle tempo-synced movers & neon perimeter glow | P3: Generative ambient visuals mapped across primary LED wall | Q3: Low haze output (15%) for beam visibility | R3: Support DJ on riser; stage monitors balanced | S3: Scheduled | T3: FALSE | U3: Beverage and canapé service in full circulation across El Patio | V3: Julian Clarkson | W3: 46297.413 | X3: 46297.413
A4: ROS-003 | B4: GHXSTSHIP | C4: CSMIA26 | D4: 5000-OPR-007 | E4: CUE-03 | F4: Act II · Official Opening & Remarks | G4: Executive Welcome & Opening Remarks | H4: Formal welcome remarks by Isabella Acker (Spotify) and Ashley Sumner (Tigre) | I4: 0.8125 | J4: 0.82291667 | K4: 15 | L4: LOC-01 | M4: P-021 | N4: DJ track fade to bed; wireless handheld mics 1 & 2 live at 82 dBA | O4: Look 03 - Crisp keylight wash center-stage; house ambient dimmed 50% | P4: Presentation title slide; live IMAG feed on stage side blades | Q4: Haze paused; clear atmosphere for clear sightlines | R4: Speakers escorted to downstage right; lectern placed center | S4: Scheduled | T4: FALSE | U4: Broadcast feed live recording enabled; timecode sync verified | V4: Julian Clarkson | W4: 46297.413 | X4: 46297.413
A5: ROS-004 | B5: GHXSTSHIP | C5: CSMIA26 | D5: 5000-OPR-007 | E5: CUE-04 | F5: Act II · Official Opening & Remarks | G5: Brand Sizzle & Artist Video Reveal | H5: Dynamic video sizzle reveal showcasing Casa Spotify artist partnerships | I5: 0.82291667 | J5: 0.83333333 | K5: 15 | L5: LOC-01 | M5: P-021 | N5: 5.1 surround sizzle audio playback from media server at 90 dBA | O5: Look 04 - Complete blackout into pulsing emerald/cyan strobes | P5: Full-resolution 4K branded sizzle reel playing on main LED wall | Q5: Cryo CO2 jet single burst on final beat drop | R5: Lectern struck to stage left; headline backline powered hot | S5: Scheduled | T5: FALSE | U5: Headliner escorted from Artist Village Green Room (LOC-06) to stage wing | V5: Julian Clarkson | W5: 46297.413 | X5: 46297.413
A6: ROS-005 | B6: GHXSTSHIP | C6: CSMIA26 | D6: 5000-OPR-007 | E6: CUE-05 | F6: Act III · Headline Performance | G6: Headliner Live Performance (Set 1) | H6: Featured headliner live performance and full concert presentation | I6: 0.83333333 | J6: 0.88541667 | K6: 75 | L6: LOC-01 | M6: P-024 | N6: Full line array concert mix, cardioid sub engagement at 98 dBA | O6: Look 05 - High-energy programmed movers, beam sweeps & pixel tape | P6: Live artist-synced reactive visuals & dynamic multi-cam IMAG | Q6: Cold-spark fountains on track climax; medium atmospheric haze (30%) | R6: Headliner on stage; audio tech standing by stage left | S6: Scheduled | T6: FALSE | U6: Noise monitor logging compliance at Biscayne property perimeter | V6: Julian Clarkson | W6: 46297.413 | X6: 46297.413
A7: ROS-006 | B7: GHXSTSHIP | C7: CSMIA26 | D7: 5000-OPR-007 | E7: CUE-06 | F7: Act III · Headline Performance | G7: Guest Artist Collab & Show Finale | H7: Surprise guest artist collaboration and peak performance finale | I7: 0.88541667 | J7: 0.91666667 | K7: 45 | L7: LOC-01 | M7: P-024 | N7: Guest wireless vocal channels unmuted; peak concert mix at 100 dBA | O7: Look 06 - Audience blinders full, laser aerial fan & 360 strobe sweeps | P7: High-contrast synchronized strobe visual packages across all screens | Q7: Continuous CO2 cryo cannon bursts & biodegradable confetti drop | R7: Guest artist escort onto stage right; stagehands on perimeter | S7: Scheduled | T7: FALSE | U7: Photographers alerted for hero capture moment; security perimeter alert | V7: Julian Clarkson | W7: 46297.413 | X7: 46297.413
A8: ROS-007 | B8: GHXSTSHIP | C8: CSMIA26 | D8: 5000-OPR-007 | E8: CUE-07 | F8: Act IV · Cool-Down & Egress | G8: After-Show DJ & Late-Night Bites | H8: Artist bow, transition to after-hours lounge format, and late-night food cart | I8: 0.91666667 | J8: 0.95833333 | K8: 60 | L8: LOC-01 | M8: P-021 | N8: Live PA transition to downtempo lounge playlist at 80 dBA | O8: Look 07 - Warm golden-hour lounge state; stage movers to static focus | P8: Event recap reel loop & partner appreciation graphic credits | Q8: SFX systems fully safe and isolated; haze exhausted | R8: Headliners escorted to private hospitality lounge; backline isolated | S8: Scheduled | T8: FALSE | U8: Late-night street food carts active on El Patio; rideshare hub dispatch | V8: Julian Clarkson | W8: 46297.413 | X8: 46297.413
A9: ROS-008 | B9: GHXSTSHIP | C9: CSMIA26 | D9: 5000-OPR-007 | E9: CUE-08 | F9: Act IV · Cool-Down & Egress | G9: Final Egress, Load-Out & Space Restoration | H9: Venue doors close; orderly patron egress, initial strike, and custodial turnaround | I9: 0.95833333 | J9: 0.98958333 | K9: 45 | L9: LOC-17 | M9: P-016 | N9: Curfew audio mute; system standby and console shutdown | O9: Look 08 - Full work lights up; exterior security flood illumination | P9: Displays powered down into standby mode | Q9: Systems depressurized and lockbox secured | R9: Overhire stagehands load-in; rolling backline cases to dock A | S9: Scheduled | T9: FALSE | U9: Incident CAD log closed; security sweep verified; venue dark call | V9: Julian Clarkson | W9: 46297.413 | X9: 46297.413

Sheet SOP Library
A1: SOP ID | B1: TITLE | C1: OPERATIONAL DOMAIN | D1: REVISION | E1: ORGANIZATION | F1: PROJECT | G1: DEPARTMENT | H1: CATEGORY | I1: SUB CATEGORY | J1: ACCOUNTABLE ROLE CODE | K1: ACCOUNTABLE ROLE TITLE | L1: REQUIRED PPE / COMPLIANCE TAG | M1: PREREQUISITES & HAZARDS | N1: PROCEDURE STEP 1 | O1: PROCEDURE STEP 2 | P1: PROCEDURE STEP 3 | Q1: PROCEDURE STEP 4 | R1: REFERENCE DOC ID | S1: REFERENCE DOCUMENT NAME | T1: STATUS | U1: FLAG | V1: NOTES | W1: CREATED BY | X1: CREATED AT | Y1: UPDATED AT
A2: SOP-001 | B2: Overhead Rigging & Motor Inspection Protocol | C2: Structural & Rigging Safety | D2: v2.0 | G2: 5000 Production | H2: 5000.05.02 | I2: Overhead Rigging | J2: 5000.51.02 | K2: {=_xlfn.XLOOKUP(J2, 'Roles Library'!$A$2:$A100, 'Roles Library'!$B$2:$B100, "")} -> Head Arena / Festival Rigger | L2: TAG-002 OSHA · TAG-022 ETCP · Hard Hat, ANSI Steel-Toe Boots, High-Vis Vest, Fall Arrest Harness | M2: Verify structural stamped load capacity (DOC-004), verify clear drop zone below trusses, and lock out ground personnel. | N2: Pre-Rig Inspection: Inspect all 1-ton CM lodestar chain hoists, steel cables, shackles, and Spansets for wear, deformation, or certification expiration. | O2: Bridle & Point Hanging: Attach engineered beam clamps to approved building structural nodes per stamped plot; rig motor hoist cables with safety secondary. | P2: Truss Assembly & Dead-Hang Proof: Pin 20.5-inch box truss sections; run cable looms; perform dead-lift test bump to 3 feet; verify shackle mousing and weight distribution. | Q2: Trim Height Lockout: Hoist rig to final trim elevation (22 ft); engage secondary safety safeties/steel chokers; tag out controller box at FOH. | R2: DOC-004 | S2: {=_xlfn.XLOOKUP(R2, 'Document & Asset Library'!$A$2:$A100, 'Document & Asset Library'!$B$2:$B100, "")} -> Overhead Rigging Plot & Stamped Structural Analysis | T2: Active | U2: FALSE | V2: OSHA & ETCP compliant overhead rigging inspection procedure. | W2: Julian Clarkson | X2: 46297.413 | Y2: 46297
A3: SOP-002 | B3: Temporary Event Power Distribution & Generator Energization | C3: High-Voltage Electrical Safety | D3: v1.2 | G3: 5000 Production | H3: 5000.06.01 | I3: Electrical Distribution | J3: 5000.50.02 | K3: {=_xlfn.XLOOKUP(J3, 'Roles Library'!$A$2:$A100, 'Roles Library'!$B$2:$B100, "")} -> Master Electrician / Power Lead | L3: TAG-002 OSHA · TAG-041 NEC · NFPA 70E Arc-Flash Face Shield, Class 0 Insulated Gloves, Safety Glasses | M3: Permit EL-2026-04421 on file (DOC-003); 400A diesel generator grounded to 25 ohms or less; lockout/tagout in effect. | N3: Grounding & Feeder Lay: Drive copper grounding rod; test soil resistance with earth ground meter; lay 4/0 AWG feeder runs in heavy-duty yellow jacket cable ramps. | O3: Cam-Lock Connection Sequence: Connect Ground (Green), Neutral (White), Phase C (Blue), Phase B (Red), Phase A (Black) in strict NEC sequence. | P3: Energization & Phase Rotation: Power generator to 60 Hz idle; verify phase voltage (120V/208V 3-phase) and rotation meter before closing main distribution breaker. | Q3: Sub-Distro Branch Load Balancing: Energize audio, lighting, and video distribution boxes sequentially; monitor balanced amp draw across all 3 legs (max 80% derate). | R3: DOC-003 | S3: {=_xlfn.XLOOKUP(R3, 'Document & Asset Library'!$A$2:$A100, 'Document & Asset Library'!$B$2:$B100, "")} -> Temporary Power & Generator Tie-In Permit & Load Calc | T3: Active | U3: FALSE | V3: NEC & NFPA 70E temporary power tie-in and generator energization protocol. | W3: Julian Clarkson | X3: 46297.413 | Y3: 46297
A4: SOP-003 | B4: Concert Line Array Tuning & Perimeter SPL Curfew Enforcement | C4: Acoustic Systems & Municipal Compliance | D4: v2.0 | G4: 5000 Production | H4: 5000.01.02 | I4: Audio Engineering | J4: 9000.50.02 | K4: {=_xlfn.XLOOKUP(J4, 'Roles Library'!$A$2:$A100, 'Roles Library'!$B$2:$B100, "")} -> Audio Engineer - A1/FOH | L4: TAG-002 OSHA · Hearing Protection (Custom Molded / High-Fidelity Earplugs) | M4: EASE plot alignment confirmed (DOC-005); SMAART acoustic measurement rig calibrated; stage clear of non-audio crew. | N4: Pink Noise Line Check & Phase Verification: Sweep pink noise through individual speaker elements (tops, downfills, subs); confirm polarity and phase coherence in SMAART. | O4: Cardioid Sub Optimization: Align delay and phase cancellation on rear-facing sub elements to create 18dB rear rejection toward Biscayne property boundary. | P4: System EQ & Target Curve Voicing: Apply room curve filtering for vocal clarity and dynamic range; tune FOH mix position to target 98 dBA Leq (15 min). | Q4: Perimeter Curfew Logging: Deploy remote Type 2 sound level meter at property edge; continuously record calibrated SPL to verify <78 dBA compliance through midnight. | R4: DOC-005 | S4: {=_xlfn.XLOOKUP(R4, 'Document & Asset Library'!$A$2:$A100, 'Document & Asset Library'!$B$2:$B100, "")} -> Acoustic Sound Modeling & SPL Compliance Plan | T4: Active | U4: FALSE | V4: Acoustic line array tuning and Biscayne perimeter SPL curfew compliance. | W4: Julian Clarkson | X4: 46297.413 | Y4: 46297
A5: SOP-004 | B5: Severe Weather Monitoring & Temporary Structure Evacuation | C5: Life Safety & Weather Trigger Management | D5: v1.5 | G5: 6000 Operations | H5: 6000.05.01 | I5: Severe Weather & Egress | J5: 6000.50.02 | K5: {=_xlfn.XLOOKUP(J5, 'Roles Library'!$A$2:$A100, 'Roles Library'!$B$2:$B100, "")} -> Site Safety & Security Lead | L5: TAG-002 OSHA · TAG-019 NFPA · Weatherproof Tactical Hi-Vis Outerwear, Flashlight, Two-Way Radio (Channel 1) | M5: On-site calibrated anemometer active; live radar weather monitoring feed connected; Emergency Action Plan active (DOC-008). | N5: Advisory State (25 MPH Gusts / Lightning <15 Miles): Notify Executive Producer and Department Heads via Radio Ch 1; inspect tent ballasts and loose signage. | O5: Restricted State (35 MPH Gusts / Lightning <8 Miles): Pause high-altitude staging/aerial lifts; lower flying LED walls to safety deck; pause patio dining service. | P5: Evacuation Trigger (45 MPH Gusts / Lightning <5 Miles): Trigger mass notification; illuminate emergency work lights; activate orderly egress toward indoor sanctuary (LOC-01). | Q5: Post-Storm All-Clear & Inspection: Conduct structural engineering inspection of outdoor canopies, rigging points, and electrical lines before re-admitting guests. | R5: DOC-008 | S5: {=_xlfn.XLOOKUP(R5, 'Document & Asset Library'!$A$2:$A100, 'Document & Asset Library'!$B$2:$B100, "")} -> Comprehensive Emergency Action & Severe Weather Plan | T5: Active | U5: FALSE | V5: Severe weather action levels and temporary structure evacuation protocol. | W5: Julian Clarkson | X5: 46297.413 | Y5: 46297
A6: SOP-005 | B6: Assembly Occupancy Ingress & Egress Door Control | C6: Crowd Management & Fire Code Compliance | D6: v1.0 | G6: 6000 Operations | H6: 6000.50.01 | I6: House Management | J6: 6000.50.01 | K6: {=_xlfn.XLOOKUP(J6, 'Roles Library'!$A$2:$A100, 'Roles Library'!$B$2:$B100, "")} -> House Manager | L6: TAG-002 OSHA · TAG-006 ADA · Certified Crowd Manager Badge, Hi-Vis Identification Lanyard | M6: Assembly permit BD-2026-08914 approved (DOC-002); master egress widths verified (DOC-001); minimum 8 crowd managers on post. | N6: Pre-Ingress Life Safety Walk: Walk all exit corridors, panic hardware, emergency illuminated exit signs, and fire extinguisher stations; verify zero pathway obstructions. | O6: Queue Line Stanchion Configuration: Establish ADA-compliant arrival switchbacks (36-inch clear path); position RFID scanners; open check-in gates at T-00:30 (18:00). | P6: Capacity Flow Tracking: Monitor real-time headcount dashboard; maintain headcount under 350 occupant maximum; enforce 1-in-1-out policy if capacity reached. | Q6: Egress Call & Doors Clearance: At event conclusion (23:00), prop all double exit doors fully open; guide patron flow toward rideshare dispatch hub on 76th St. | R6: DOC-002 | S6: {=_xlfn.XLOOKUP(R6, 'Document & Asset Library'!$A$2:$A100, 'Document & Asset Library'!$B$2:$B100, "")} -> City of Miami Special Assembly Occupancy Permit | T6: Active | U6: FALSE | V6: Assembly occupancy door control and crowd manager egress coordination. | W6: Julian Clarkson | X6: 46297.413 | Y6: 46297
